2019-10-18 15:13:07.677893 >> Conectado no Banco de Dados MariaDB/MySQL....
(<class 'socketio.exceptions.ConnectionError'>, ConnectionError('Connection refused by the server'), <traceback object at 0x7fcd12fbf888>)
